<?xml version="1.0"?>
<robot name="burger_delivery_with_cars">
  <link name="table_link">
    <visual name="table_top">
      <origin xyz="0 0 0" rpy="0 0 0" />
      <geometry>
        <mesh filename="package://burger_description/meshes/cube_1m.stl" scale="1.2 0.8 0.05" />
      </geometry>
      <material name="table_brown">
        <color rgba="0.45 0.25 0.10 1.0" />
      </material>
    </visual>
    <visual name="axis_x">
      <origin xyz="0.1 0 0" rpy="0 0 0" />
      <geometry>
        <mesh filename="package://burger_description/meshes/cube_1m.stl" scale="0.2 0.01 0.01" />
      </geometry>
      <material name="axis_red">
        <color rgba="1.0 0.0 0.0 1.0" />
      </material>
    </visual>
    <visual name="axis_y">
      <origin xyz="0 0.1 0" rpy="0 0 0" />
      <geometry>
        <mesh filename="package://burger_description/meshes/cube_1m.stl" scale="0.01 0.2 0.01" />
      </geometry>
      <material name="axis_green">
        <color rgba="0.0 1.0 0.0 1.0" />
      </material>
    </visual>
    <visual name="axis_z">
      <origin xyz="0 0 0.1" rpy="0 0 0" />
      <geometry>
        <mesh filename="package://burger_description/meshes/cube_1m.stl" scale="0.01 0.01 0.2" />
      </geometry>
      <material name="axis_blue">
        <color rgba="0.0 0.2 1.0 1.0" />
      </material>
    </visual>
    <visual name="axis_x_head">
      <origin xyz="0.2 0 0" rpy="0 -1.5708 0" />
      <geometry>
        <mesh filename="package://burger_description/meshes/arrow_pyramid_1m.stl" scale="0.06 0.06 0.08" />
      </geometry>
      <material name="axis_red">
        <color rgba="1.0 0.0 0.0 1.0" />
      </material>
    </visual>
    <visual name="axis_y_head">
      <origin xyz="0 0.2 0" rpy="1.5708 0 0" />
      <geometry>
        <mesh filename="package://burger_description/meshes/arrow_pyramid_1m.stl" scale="0.06 0.06 0.08" />
      </geometry>
      <material name="axis_green">
        <color rgba="0.0 1.0 0.0 1.0" />
      </material>
    </visual>
    <visual name="axis_z_head">
      <origin xyz="0 0 0.2" rpy="0 0 0" />
      <geometry>
        <mesh filename="package://burger_description/meshes/arrow_pyramid_1m.stl" scale="0.06 0.06 0.08" />
      </geometry>
      <material name="axis_blue">
        <color rgba="0.0 0.2 1.0 1.0" />
      </material>
    </visual>
  </link>
  <link name="staging_area">
    <visual name="staging_pad">
      <geometry>
        <mesh filename="package://burger_description/meshes/cube_1m.stl" scale="0.5 0.5 0.02" />
      </geometry>
      <material name="staging_blue">
        <color rgba="0.2 0.4 0.9 0.7" />
      </material>
    </visual>
    <visual name="axis_x">
      <origin xyz="0.1 0 0" rpy="0 0 0" />
      <geometry>
        <mesh filename="package://burger_description/meshes/cube_1m.stl" scale="0.2 0.01 0.01" />
      </geometry>
      <material name="axis_red">
        <color rgba="1.0 0.0 0.0 1.0" />
      </material>
    </visual>
    <visual name="axis_y">
      <origin xyz="0 0.1 0" rpy="0 0 0" />
      <geometry>
        <mesh filename="package://burger_description/meshes/cube_1m.stl" scale="0.01 0.2 0.01" />
      </geometry>
      <material name="axis_green">
        <color rgba="0.0 1.0 0.0 1.0" />
      </material>
    </visual>
    <visual name="axis_z">
      <origin xyz="0 0 0.1" rpy="0 0 0" />
      <geometry>
        <mesh filename="package://burger_description/meshes/cube_1m.stl" scale="0.01 0.01 0.2" />
      </geometry>
      <material name="axis_blue">
        <color rgba="0.0 0.2 1.0 1.0" />
      </material>
    </visual>
    <visual name="axis_x_head">
      <origin xyz="0.2 0 0" rpy="0 -1.5708 0" />
      <geometry>
        <mesh filename="package://burger_description/meshes/arrow_pyramid_1m.stl" scale="0.06 0.06 0.08" />
      </geometry>
      <material name="axis_red">
        <color rgba="1.0 0.0 0.0 1.0" />
      </material>
    </visual>
    <visual name="axis_y_head">
      <origin xyz="0 0.2 0" rpy="1.5708 0 0" />
      <geometry>
        <mesh filename="package://burger_description/meshes/arrow_pyramid_1m.stl" scale="0.06 0.06 0.08" />
      </geometry>
      <material name="axis_green">
        <color rgba="0.0 1.0 0.0 1.0" />
      </material>
    </visual>
    <visual name="axis_z_head">
      <origin xyz="0 0 0.2" rpy="0 0 0" />
      <geometry>
        <mesh filename="package://burger_description/meshes/arrow_pyramid_1m.stl" scale="0.06 0.06 0.08" />
      </geometry>
      <material name="axis_blue">
        <color rgba="0.0 0.2 1.0 1.0" />
      </material>
    </visual>
  </link>
  <link name="delivery_slot_1">
    <visual name="delivery_slot">
      <geometry>
        <mesh filename="package://burger_description/meshes/cube_1m.stl" scale="0.2 0.2 0.1" />
      </geometry>
      <material name="slot_green">
        <color rgba="0.2 0.8 0.3 1.0" />
      </material>
    </visual>
    <visual name="axis_x">
      <origin xyz="0.1 0 0" rpy="0 0 0" />
      <geometry>
        <mesh filename="package://burger_description/meshes/cube_1m.stl" scale="0.2 0.01 0.01" />
      </geometry>
      <material name="axis_red">
        <color rgba="1.0 0.0 0.0 1.0" />
      </material>
    </visual>
    <visual name="axis_y">
      <origin xyz="0 0.1 0" rpy="0 0 0" />
      <geometry>
        <mesh filename="package://burger_description/meshes/cube_1m.stl" scale="0.01 0.2 0.01" />
      </geometry>
      <material name="axis_green">
        <color rgba="0.0 1.0 0.0 1.0" />
      </material>
    </visual>
    <visual name="axis_z">
      <origin xyz="0 0 0.1" rpy="0 0 0" />
      <geometry>
        <mesh filename="package://burger_description/meshes/cube_1m.stl" scale="0.01 0.01 0.2" />
      </geometry>
      <material name="axis_blue">
        <color rgba="0.0 0.2 1.0 1.0" />
      </material>
    </visual>
    <visual name="axis_x_head">
      <origin xyz="0.2 0 0" rpy="0 -1.5708 0" />
      <geometry>
        <mesh filename="package://burger_description/meshes/arrow_pyramid_1m.stl" scale="0.06 0.06 0.08" />
      </geometry>
      <material name="axis_red">
        <color rgba="1.0 0.0 0.0 1.0" />
      </material>
    </visual>
    <visual name="axis_y_head">
      <origin xyz="0 0.2 0" rpy="1.5708 0 0" />
      <geometry>
        <mesh filename="package://burger_description/meshes/arrow_pyramid_1m.stl" scale="0.06 0.06 0.08" />
      </geometry>
      <material name="axis_green">
        <color rgba="0.0 1.0 0.0 1.0" />
      </material>
    </visual>
    <visual name="axis_z_head">
      <origin xyz="0 0 0.2" rpy="0 0 0" />
      <geometry>
        <mesh filename="package://burger_description/meshes/arrow_pyramid_1m.stl" scale="0.06 0.06 0.08" />
      </geometry>
      <material name="axis_blue">
        <color rgba="0.0 0.2 1.0 1.0" />
      </material>
    </visual>
  </link>
  <link name="kinova_base_link">
    <visual name="kinova_base">
      <geometry>
        <mesh filename="package://burger_description/meshes/cube_1m.stl" scale="0.2 0.2 0.1" />
      </geometry>
      <material name="kinova_base_gray">
        <color rgba="0.5 0.5 0.5 1.0" />
      </material>
    </visual>
    <visual name="axis_x">
      <origin xyz="0.1 0 0" rpy="0 0 0" />
      <geometry>
        <mesh filename="package://burger_description/meshes/cube_1m.stl" scale="0.2 0.01 0.01" />
      </geometry>
      <material name="axis_red">
        <color rgba="1.0 0.0 0.0 1.0" />
      </material>
    </visual>
    <visual name="axis_y">
      <origin xyz="0 0.1 0" rpy="0 0 0" />
      <geometry>
        <mesh filename="package://burger_description/meshes/cube_1m.stl" scale="0.01 0.2 0.01" />
      </geometry>
      <material name="axis_green">
        <color rgba="0.0 1.0 0.0 1.0" />
      </material>
    </visual>
    <visual name="axis_z">
      <origin xyz="0 0 0.1" rpy="0 0 0" />
      <geometry>
        <mesh filename="package://burger_description/meshes/cube_1m.stl" scale="0.01 0.01 0.2" />
      </geometry>
      <material name="axis_blue">
        <color rgba="0.0 0.2 1.0 1.0" />
      </material>
    </visual>
    <visual name="axis_x_head">
      <origin xyz="0.2 0 0" rpy="0 -1.5708 0" />
      <geometry>
        <mesh filename="package://burger_description/meshes/arrow_pyramid_1m.stl" scale="0.06 0.06 0.08" />
      </geometry>
      <material name="axis_red">
        <color rgba="1.0 0.0 0.0 1.0" />
      </material>
    </visual>
    <visual name="axis_y_head">
      <origin xyz="0 0.2 0" rpy="1.5708 0 0" />
      <geometry>
        <mesh filename="package://burger_description/meshes/arrow_pyramid_1m.stl" scale="0.06 0.06 0.08" />
      </geometry>
      <material name="axis_green">
        <color rgba="0.0 1.0 0.0 1.0" />
      </material>
    </visual>
    <visual name="axis_z_head">
      <origin xyz="0 0 0.2" rpy="0 0 0" />
      <geometry>
        <mesh filename="package://burger_description/meshes/arrow_pyramid_1m.stl" scale="0.06 0.06 0.08" />
      </geometry>
      <material name="axis_blue">
        <color rgba="0.0 0.2 1.0 1.0" />
      </material>
    </visual>
  </link>
  <link name="kinova_tool_frame">
    <visual name="kinova_tool">
      <geometry>
        <mesh filename="package://burger_description/meshes/cube_1m.stl" scale="0.06 0.06 0.06" />
      </geometry>
      <material name="tool_orange">
        <color rgba="0.9 0.5 0.2 1.0" />
      </material>
    </visual>
    <visual name="axis_x">
      <origin xyz="0.1 0 0" rpy="0 0 0" />
      <geometry>
        <mesh filename="package://burger_description/meshes/cube_1m.stl" scale="0.2 0.01 0.01" />
      </geometry>
      <material name="axis_red">
        <color rgba="1.0 0.0 0.0 1.0" />
      </material>
    </visual>
    <visual name="axis_y">
      <origin xyz="0 0.1 0" rpy="0 0 0" />
      <geometry>
        <mesh filename="package://burger_description/meshes/cube_1m.stl" scale="0.01 0.2 0.01" />
      </geometry>
      <material name="axis_green">
        <color rgba="0.0 1.0 0.0 1.0" />
      </material>
    </visual>
    <visual name="axis_z">
      <origin xyz="0 0 0.1" rpy="0 0 0" />
      <geometry>
        <mesh filename="package://burger_description/meshes/cube_1m.stl" scale="0.01 0.01 0.2" />
      </geometry>
      <material name="axis_blue">
        <color rgba="0.0 0.2 1.0 1.0" />
      </material>
    </visual>
    <visual name="axis_x_head">
      <origin xyz="0.2 0 0" rpy="0 -1.5708 0" />
      <geometry>
        <mesh filename="package://burger_description/meshes/arrow_pyramid_1m.stl" scale="0.06 0.06 0.08" />
      </geometry>
      <material name="axis_red">
        <color rgba="1.0 0.0 0.0 1.0" />
      </material>
    </visual>
    <visual name="axis_y_head">
      <origin xyz="0 0.2 0" rpy="1.5708 0 0" />
      <geometry>
        <mesh filename="package://burger_description/meshes/arrow_pyramid_1m.stl" scale="0.06 0.06 0.08" />
      </geometry>
      <material name="axis_green">
        <color rgba="0.0 1.0 0.0 1.0" />
      </material>
    </visual>
    <visual name="axis_z_head">
      <origin xyz="0 0 0.2" rpy="0 0 0" />
      <geometry>
        <mesh filename="package://burger_description/meshes/arrow_pyramid_1m.stl" scale="0.06 0.06 0.08" />
      </geometry>
      <material name="axis_blue">
        <color rgba="0.0 0.2 1.0 1.0" />
      </material>
    </visual>
  </link>
  <link name="burger_grip_frame">
    <visual name="burger_grip">
      <geometry>
        <mesh filename="package://burger_description/meshes/cube_1m.stl" scale="0.04 0.08 0.02" />
      </geometry>
      <material name="grip_red">
        <color rgba="0.9 0.2 0.2 1.0" />
      </material>
    </visual>
    <visual name="axis_x">
      <origin xyz="0.1 0 0" rpy="0 0 0" />
      <geometry>
        <mesh filename="package://burger_description/meshes/cube_1m.stl" scale="0.2 0.01 0.01" />
      </geometry>
      <material name="axis_red">
        <color rgba="1.0 0.0 0.0 1.0" />
      </material>
    </visual>
    <visual name="axis_y">
      <origin xyz="0 0.1 0" rpy="0 0 0" />
      <geometry>
        <mesh filename="package://burger_description/meshes/cube_1m.stl" scale="0.01 0.2 0.01" />
      </geometry>
      <material name="axis_green">
        <color rgba="0.0 1.0 0.0 1.0" />
      </material>
    </visual>
    <visual name="axis_z">
      <origin xyz="0 0 0.1" rpy="0 0 0" />
      <geometry>
        <mesh filename="package://burger_description/meshes/cube_1m.stl" scale="0.01 0.01 0.2" />
      </geometry>
      <material name="axis_blue">
        <color rgba="0.0 0.2 1.0 1.0" />
      </material>
    </visual>
    <visual name="axis_x_head">
      <origin xyz="0.2 0 0" rpy="0 -1.5708 0" />
      <geometry>
        <mesh filename="package://burger_description/meshes/arrow_pyramid_1m.stl" scale="0.06 0.06 0.08" />
      </geometry>
      <material name="axis_red">
        <color rgba="1.0 0.0 0.0 1.0" />
      </material>
    </visual>
    <visual name="axis_y_head">
      <origin xyz="0 0.2 0" rpy="1.5708 0 0" />
      <geometry>
        <mesh filename="package://burger_description/meshes/arrow_pyramid_1m.stl" scale="0.06 0.06 0.08" />
      </geometry>
      <material name="axis_green">
        <color rgba="0.0 1.0 0.0 1.0" />
      </material>
    </visual>
    <visual name="axis_z_head">
      <origin xyz="0 0 0.2" rpy="0 0 0" />
      <geometry>
        <mesh filename="package://burger_description/meshes/arrow_pyramid_1m.stl" scale="0.06 0.06 0.08" />
      </geometry>
      <material name="axis_blue">
        <color rgba="0.0 0.2 1.0 1.0" />
      </material>
    </visual>
  </link>
  
  <link name="overhead_camera_link">
    <visual name="overhead_camera">
      <geometry>
        <mesh filename="package://burger_description/meshes/cube_1m.stl" scale="0.05 0.05 0.05" />
      </geometry>
      <material name="cam_black">
        <color rgba="0.1 0.1 0.1 1.0" />
      </material>
    </visual>
    <visual name="axis_x">
      <origin xyz="0.1 0 0" rpy="0 0 0" />
      <geometry>
        <mesh filename="package://burger_description/meshes/cube_1m.stl" scale="0.2 0.01 0.01" />
      </geometry>
      <material name="axis_red">
        <color rgba="1.0 0.0 0.0 1.0" />
      </material>
    </visual>
    <visual name="axis_y">
      <origin xyz="0 0.1 0" rpy="0 0 0" />
      <geometry>
        <mesh filename="package://burger_description/meshes/cube_1m.stl" scale="0.01 0.2 0.01" />
      </geometry>
      <material name="axis_green">
        <color rgba="0.0 1.0 0.0 1.0" />
      </material>
    </visual>
    <visual name="axis_z">
      <origin xyz="0 0 0.1" rpy="0 0 0" />
      <geometry>
        <mesh filename="package://burger_description/meshes/cube_1m.stl" scale="0.01 0.01 0.2" />
      </geometry>
      <material name="axis_blue">
        <color rgba="0.0 0.2 1.0 1.0" />
      </material>
    </visual>
    <visual name="axis_x_head">
      <origin xyz="0.2 0 0" rpy="0 -1.5708 0" />
      <geometry>
        <mesh filename="package://burger_description/meshes/arrow_pyramid_1m.stl" scale="0.06 0.06 0.08" />
      </geometry>
      <material name="axis_red">
        <color rgba="1.0 0.0 0.0 1.0" />
      </material>
    </visual>
    <visual name="axis_y_head">
      <origin xyz="0 0.2 0" rpy="1.5708 0 0" />
      <geometry>
        <mesh filename="package://burger_description/meshes/arrow_pyramid_1m.stl" scale="0.06 0.06 0.08" />
      </geometry>
      <material name="axis_green">
        <color rgba="0.0 1.0 0.0 1.0" />
      </material>
    </visual>
    <visual name="axis_z_head">
      <origin xyz="0 0 0.2" rpy="0 0 0" />
      <geometry>
        <mesh filename="package://burger_description/meshes/arrow_pyramid_1m.stl" scale="0.06 0.06 0.08" />
      </geometry>
      <material name="axis_blue">
        <color rgba="0.0 0.2 1.0 1.0" />
      </material>
    </visual>
  </link>
  <link name="map">
    <visual name="axis_x">
      <origin xyz="0.1 0 0" rpy="0 0 0" />
      <geometry>
        <mesh filename="package://burger_description/meshes/cube_1m.stl" scale="0.2 0.01 0.01" />
      </geometry>
      <material name="axis_red">
        <color rgba="1.0 0.0 0.0 1.0" />
      </material>
    </visual>
    <visual name="axis_y">
      <origin xyz="0 0.1 0" rpy="0 0 0" />
      <geometry>
        <mesh filename="package://burger_description/meshes/cube_1m.stl" scale="0.01 0.2 0.01" />
      </geometry>
      <material name="axis_green">
        <color rgba="0.0 1.0 0.0 1.0" />
      </material>
    </visual>
    <visual name="axis_z">
      <origin xyz="0 0 0.1" rpy="0 0 0" />
      <geometry>
        <mesh filename="package://burger_description/meshes/cube_1m.stl" scale="0.01 0.01 0.2" />
      </geometry>
      <material name="axis_blue">
        <color rgba="0.0 0.2 1.0 1.0" />
      </material>
    </visual>
    <visual name="axis_x_head">
      <origin xyz="0.2 0 0" rpy="0 -1.5708 0" />
      <geometry>
        <mesh filename="package://burger_description/meshes/arrow_pyramid_1m.stl" scale="0.06 0.06 0.08" />
      </geometry>
      <material name="axis_red">
        <color rgba="1.0 0.0 0.0 1.0" />
      </material>
    </visual>
    <visual name="axis_y_head">
      <origin xyz="0 0.2 0" rpy="1.5708 0 0" />
      <geometry>
        <mesh filename="package://burger_description/meshes/arrow_pyramid_1m.stl" scale="0.06 0.06 0.08" />
      </geometry>
      <material name="axis_green">
        <color rgba="0.0 1.0 0.0 1.0" />
      </material>
    </visual>
    <visual name="axis_z_head">
      <origin xyz="0 0 0.2" rpy="0 0 0" />
      <geometry>
        <mesh filename="package://burger_description/meshes/arrow_pyramid_1m.stl" scale="0.06 0.06 0.08" />
      </geometry>
      <material name="axis_blue">
        <color rgba="0.0 0.2 1.0 1.0" />
      </material>
    </visual>
  </link>
  <joint name="map_to_table" type="fixed">
    <parent link="map" />
    <child link="table_link" />
    <origin xyz="0.80 -1.00 0.80" rpy="0 0 0" />
  </joint>
  <joint name="map_to_staging" type="fixed">
    <parent link="map" />
    <child link="staging_area" />
    <origin xyz="0.80 0.00 0.00" rpy="0 0 0" />
  </joint>
  <joint name="staging_to_delivery_slot_1" type="fixed">
    <parent link="staging_area" />
    <child link="delivery_slot_1" />
    <origin xyz="0.00 0.40 0.50" rpy="0 0 0" />
  </joint>
  <joint name="map_to_kinova_base" type="fixed">
    <parent link="table_link" />
    <child link="kinova_base_link" />
    <origin xyz="1.20 0.30 0.5" rpy="0 0 0" />
  </joint>
  <joint name="kinova_base_to_tool" type="fixed">
    <parent link="kinova_base_link" />
    <child link="kinova_tool_frame" />
    <origin xyz="0 0 0.0" rpy="0 0 0" />
  </joint>
  <joint name="tool_to_grip" type="fixed">
    <parent link="kinova_tool_frame" />
    <child link="burger_grip_frame" />
    <origin xyz="0 0 0.18" rpy="0 0 0" />
  </joint>
  
  <joint name="map_to_robot_a_base" type="fixed">
    <parent link="map" />
    <child link="car1_base_link" />
    <origin xyz="1.20 0.80 0.00" rpy="0 0 0" />
  </joint>
  
  <joint name="map_to_robot_b_base" type="fixed">
    <parent link="map" />
    <child link="car2_base_link" />
    <origin xyz="1.20 1.30 0.00" rpy="0 0 0" />
  </joint>
  
  <joint name="map_to_camera" type="fixed">
    <parent link="map" />
    <child link="overhead_camera_link" />
    <origin xyz="2.00 1.00 1.50" rpy="0 0.5 -1.5708" />
  </joint>
  <joint name="map_to_world" type="fixed">
    <parent link="table_link" />
    <child link="world" />
    <origin xyz="0.20 0.30 0.00" rpy="0 0 0" />
  </joint>
  <link name="world" />
  <material name="aluminum">
    <color rgba="0.5 0.5 0.5 1" />
  </material>
  <material name="plastic">
    <color rgba="0.1 0.1 0.1 1" />
  </material>
  <ros2_control name="gen3_KortexMultiInterfaceHardware" type="system">
    <hardware>
      <plugin>kortex2_driver/KortexMultiInterfaceHardware</plugin>
      <param name="robot_ip">192.168.11.11</param>
      <param name="username">admin</param>
      <param name="password">admin</param>
      <param name="port">10000</param>
      <param name="port_realtime">10001</param>
      <param name="session_inactivity_timeout_ms">60000</param>
      <param name="connection_inactivity_timeout_ms">2000</param>
      <param name="tf_prefix">""</param>
      <param name="use_internal_bus_gripper_comm">False</param>
      <param name="gripper_joint_name">finger_joint</param>
    </hardware>
    <joint name="gen3_joint_1">
      <command_interface name="position">
        <param name="min">${-2*pi}</param>
        <param name="max">${2*pi}</param>
      </command_interface>
      <command_interface name="velocity">
        <param name="min">-3.15</param>
        <param name="max">3.15</param>
      </command_interface>
      <state_interface name="position">
        <param name="initial_value">0.0</param>
      </state_interface>
      <state_interface name="velocity" />
      <state_interface name="effort" />
    </joint>
    <joint name="gen3_joint_2">
      <command_interface name="position">
        <param name="min">-2.41</param>
        <param name="max">2.41</param>
      </command_interface>
      <command_interface name="velocity">
        <param name="min">-3.15</param>
        <param name="max">3.15</param>
      </command_interface>
      <state_interface name="position">
        <param name="initial_value">0.0</param>
      </state_interface>
      <state_interface name="velocity" />
      <state_interface name="effort" />
    </joint>
    <joint name="gen3_joint_3">
      <command_interface name="position">
        <param name="min">${-2*pi}</param>
        <param name="max">${2*pi}</param>
      </command_interface>
      <command_interface name="velocity">
        <param name="min">-3.15</param>
        <param name="max">3.15</param>
      </command_interface>
      <state_interface name="position">
        <param name="initial_value">0.0</param>
      </state_interface>
      <state_interface name="velocity" />
      <state_interface name="effort" />
    </joint>
    <joint name="gen3_joint_4">
      <command_interface name="position">
        <param name="min">-2.66</param>
        <param name="max">2.66</param>
      </command_interface>
      <command_interface name="velocity">
        <param name="min">-3.2</param>
        <param name="max">3.2</param>
      </command_interface>
      <state_interface name="position">
        <param name="initial_value">0.0</param>
      </state_interface>
      <state_interface name="velocity" />
      <state_interface name="effort" />
    </joint>
    <joint name="gen3_joint_5">
      <command_interface name="position">
        <param name="min">${-2*pi}</param>
        <param name="max">${2*pi}</param>
      </command_interface>
      <command_interface name="velocity">
        <param name="min">-3.2</param>
        <param name="max">3.2</param>
      </command_interface>
      <state_interface name="position">
        <param name="initial_value">0.0</param>
      </state_interface>
      <state_interface name="velocity" />
      <state_interface name="effort" />
    </joint>
    <joint name="gen3_joint_6">
      <command_interface name="position">
        <param name="min">-2.23</param>
        <param name="max">2.23</param>
      </command_interface>
      <command_interface name="velocity">
        <param name="min">-3.2</param>
        <param name="max">3.2</param>
      </command_interface>
      <state_interface name="position">
        <param name="initial_value">0.0</param>
      </state_interface>
      <state_interface name="velocity" />
      <state_interface name="effort" />
    </joint>
    <joint name="gen3_joint_7">
      <command_interface name="position">
        <param name="min">${-2*pi}</param>
        <param name="max">${2*pi}</param>
      </command_interface>
      <command_interface name="velocity">
        <param name="min">-3.2</param>
        <param name="max">3.2</param>
      </command_interface>
      <state_interface name="position">
        <param name="initial_value">0.0</param>
      </state_interface>
      <state_interface name="velocity" />
      <state_interface name="effort" />
    </joint>
  </ros2_control>
  <joint name="gen3_base_joint" type="fixed">
    <origin rpy="0 0 0" xyz="0 0 0" />
    <parent link="world" />
    <child link="gen3_base_link" />
  </joint>
  <link name="gen3_base_link">
    <inertial>
      <origin rpy="0 0 0" xyz="-0.000648 -0.000166 0.084487" />
      <mass value="1.697" />
      <inertia ixx="0.004622" ixy="9E-06" ixz="6E-05" iyy="0.004495" iyz="9E-06" izz="0.002079" />
    </inertial>
    <visual>
      <origin rpy="0 0 0" xyz="0 0 0" />
      <geometry>
        <mesh filename="package://burger_description/vendor/kortex_description/arms/gen3/7dof/meshes/base_link.dae" />
      </geometry>
      <material name="">
        <color rgba="0.75294 0.75294 0.75294 1" />
      </material>
    </visual>
    <collision>
      <origin rpy="0 0 0" xyz="0 0 0" />
      <geometry>
        <mesh filename="package://burger_description/vendor/kortex_description/arms/gen3/7dof/meshes/base_link.dae" />
      </geometry>
    </collision>
  </link>
  <link name="gen3_shoulder_link">
    <inertial>
      <origin rpy="0 0 0" xyz="-2.3E-05 -0.010364 -0.07336" />
      <mass value="1.3773" />
      <inertia ixx="0.00457" ixy="1E-06" ixz="2E-06" iyy="0.004831" iyz="0.000448" izz="0.001409" />
    </inertial>
    <visual>
      <origin rpy="0 0 0" xyz="0 0 0" />
      <geometry>
        <mesh filename="package://burger_description/vendor/kortex_description/arms/gen3/7dof/meshes/shoulder_link.dae" />
      </geometry>
      <material name="">
        <color rgba="0.75294 0.75294 0.75294 1" />
      </material>
    </visual>
    <collision>
      <origin rpy="0 0 0" xyz="0 0 0" />
      <geometry>
        <mesh filename="package://burger_description/vendor/kortex_description/arms/gen3/7dof/meshes/shoulder_link.dae" />
      </geometry>
    </collision>
  </link>
  <joint name="gen3_joint_1" type="continuous">
    <origin rpy="3.1416 2.7629E-18 -4.9305E-36" xyz="0 0 0.15643" />
    <parent link="gen3_base_link" />
    <child link="gen3_shoulder_link" />
    <axis xyz="0 0 1" />
    <limit effort="39" velocity="1.3963" />
  </joint>
  <link name="gen3_half_arm_1_link">
    <inertial>
      <origin rpy="0 0 0" xyz="-4.4E-05 -0.09958 -0.013278" />
      <mass value="1.1636" />
      <inertia ixx="0.011088" ixy="5E-06" ixz="0" iyy="0.001072" iyz="-0.000691" izz="0.011255" />
    </inertial>
    <visual>
      <origin rpy="0 0 0" xyz="0 0 0" />
      <geometry>
        <mesh filename="package://burger_description/vendor/kortex_description/arms/gen3/7dof/meshes/half_arm_1_link.dae" />
      </geometry>
      <material name="">
        <color rgba="0.75294 0.75294 0.75294 1" />
      </material>
    </visual>
    <collision>
      <origin rpy="0 0 0" xyz="0 0 0" />
      <geometry>
        <mesh filename="package://burger_description/vendor/kortex_description/arms/gen3/7dof/meshes/half_arm_1_link.dae" />
      </geometry>
    </collision>
  </link>
  <joint name="gen3_joint_2" type="revolute">
    <origin rpy="1.5708 2.1343E-17 -1.1102E-16" xyz="0 0.005375 -0.12838" />
    <parent link="gen3_shoulder_link" />
    <child link="gen3_half_arm_1_link" />
    <axis xyz="0 0 1" />
    <limit effort="39" lower="-2.41" upper="2.41" velocity="1.3963" />
  </joint>
  <link name="gen3_half_arm_2_link">
    <inertial>
      <origin rpy="0 0 0" xyz="-4.4E-05 -0.006641 -0.117892" />
      <mass value="1.1636" />
      <inertia ixx="0.010932" ixy="0" ixz="-7E-06" iyy="0.011127" iyz="0.000606" izz="0.001043" />
    </inertial>
    <visual>
      <origin rpy="0 0 0" xyz="0 0 0" />
      <geometry>
        <mesh filename="package://burger_description/vendor/kortex_description/arms/gen3/7dof/meshes/half_arm_2_link.dae" />
      </geometry>
      <material name="">
        <color rgba="0.75294 0.75294 0.75294 1" />
      </material>
    </visual>
    <collision>
      <origin rpy="0 0 0" xyz="0 0 0" />
      <geometry>
        <mesh filename="package://burger_description/vendor/kortex_description/arms/gen3/7dof/meshes/half_arm_2_link.dae" />
      </geometry>
    </collision>
  </link>
  <joint name="gen3_joint_3" type="continuous">
    <origin rpy="-1.5708 1.2326E-32 -2.9122E-16" xyz="0 -0.21038 -0.006375" />
    <parent link="gen3_half_arm_1_link" />
    <child link="gen3_half_arm_2_link" />
    <axis xyz="0 0 1" />
    <limit effort="39" velocity="1.3963" />
  </joint>
  <link name="gen3_forearm_link">
    <inertial>
      <origin rpy="0 0 0" xyz="-1.8E-05 -0.075478 -0.015006" />
      <mass value="0.9302" />
      <inertia ixx="0.008147" ixy="-1E-06" ixz="0" iyy="0.000631" iyz="-0.0005" izz="0.008316" />
    </inertial>
    <visual>
      <origin rpy="0 0 0" xyz="0 0 0" />
      <geometry>
        <mesh filename="package://burger_description/vendor/kortex_description/arms/gen3/7dof/meshes/forearm_link.dae" />
      </geometry>
      <material name="">
        <color rgba="0.75294 0.75294 0.75294 1" />
      </material>
    </visual>
    <collision>
      <origin rpy="0 0 0" xyz="0 0 0" />
      <geometry>
        <mesh filename="package://burger_description/vendor/kortex_description/arms/gen3/7dof/meshes/forearm_link.dae" />
      </geometry>
    </collision>
  </link>
  <joint name="gen3_joint_4" type="revolute">
    <origin rpy="1.5708 -6.6954E-17 -1.6653E-16" xyz="0 0.006375 -0.21038" />
    <parent link="gen3_half_arm_2_link" />
    <child link="gen3_forearm_link" />
    <axis xyz="0 0 1" />
    <limit effort="39" lower="-2.66" upper="2.66" velocity="1.3963" />
  </joint>
  <link name="gen3_spherical_wrist_1_link">
    <inertial>
      <origin rpy="0 0 0" xyz="1E-06 -0.009432 -0.063883" />
      <mass value="0.6781" />
      <inertia ixx="0.001596" ixy="0" ixz="0" iyy="0.001607" iyz="0.000256" izz="0.000399" />
    </inertial>
    <visual>
      <origin rpy="0 0 0" xyz="0 0 0" />
      <geometry>
        <mesh filename="package://burger_description/vendor/kortex_description/arms/gen3/7dof/meshes/spherical_wrist_1_link.dae" />
      </geometry>
      <material name="">
        <color rgba="0.75294 0.75294 0.75294 1" />
      </material>
    </visual>
    <collision>
      <origin rpy="0 0 0" xyz="0 0 0" />
      <geometry>
        <mesh filename="package://burger_description/vendor/kortex_description/arms/gen3/7dof/meshes/spherical_wrist_1_link.dae" />
      </geometry>
    </collision>
  </link>
  <joint name="gen3_joint_5" type="continuous">
    <origin rpy="-1.5708 2.2204E-16 -6.373E-17" xyz="0 -0.20843 -0.006375" />
    <parent link="gen3_forearm_link" />
    <child link="gen3_spherical_wrist_1_link" />
    <axis xyz="0 0 1" />
    <limit effort="9" velocity="1.2218" />
  </joint>
  <link name="gen3_spherical_wrist_2_link">
    <inertial>
      <origin rpy="0 0 0" xyz="1E-06 -0.045483 -0.00965" />
      <mass value="0.6781" />
      <inertia ixx="0.001641" ixy="0" ixz="0" iyy="0.00041" iyz="-0.000278" izz="0.001641" />
    </inertial>
    <visual>
      <origin rpy="0 0 0" xyz="0 0 0" />
      <geometry>
        <mesh filename="package://burger_description/vendor/kortex_description/arms/gen3/7dof/meshes/spherical_wrist_2_link.dae" />
      </geometry>
      <material name="">
        <color rgba="0.75294 0.75294 0.75294 1" />
      </material>
    </visual>
    <collision>
      <origin rpy="0 0 0" xyz="0 0 0" />
      <geometry>
        <mesh filename="package://burger_description/vendor/kortex_description/arms/gen3/7dof/meshes/spherical_wrist_2_link.dae" />
      </geometry>
    </collision>
  </link>
  <joint name="gen3_joint_6" type="revolute">
    <origin rpy="1.5708 9.2076E-28 -8.2157E-15" xyz="0 0.00017505 -0.10593" />
    <parent link="gen3_spherical_wrist_1_link" />
    <child link="gen3_spherical_wrist_2_link" />
    <axis xyz="0 0 1" />
    <limit effort="9" lower="-2.23" upper="2.23" velocity="1.2218" />
  </joint>
  <link name="gen3_bracelet_link">
    <inertial>
      <origin rpy="0 0 0" xyz="-9.3E-05 0.000132 -0.022905" />
      <mass value="0.364" />
      <inertia ixx="0.000214" ixy="0" ixz="1E-06" iyy="0.000223" iyz="-2E-06" izz="0.00024" />
    </inertial>
    <visual>
      <origin rpy="0 0 0" xyz="0 0 0" />
      <geometry>
        <mesh filename="package://burger_description/vendor/kortex_description/arms/gen3/7dof/meshes/bracelet_no_vision_link.dae" />
      </geometry>
      <material name="">
        <color rgba="0.75294 0.75294 0.75294 1" />
      </material>
    </visual>
    <collision>
      <origin rpy="0 0 0" xyz="0 0 0" />
      <geometry>
        <mesh filename="package://burger_description/vendor/kortex_description/arms/gen3/7dof/meshes/bracelet_no_vision_link.dae" />
      </geometry>
    </collision>
  </link>
  <joint name="gen3_joint_7" type="continuous">
    <origin rpy="-1.5708 -5.5511E-17 9.6396E-17" xyz="0 -0.10593 -0.00017505" />
    <parent link="gen3_spherical_wrist_2_link" />
    <child link="gen3_bracelet_link" />
    <axis xyz="0 0 1" />
    <limit effort="9" velocity="1.2218" />
  </joint>
  <link name="gen3_end_effector_link" />
  <joint name="gen3_end_effector" type="fixed">
    <origin rpy="3.14159265358979 1.09937075168372E-32 0" xyz="0 0 -0.0615250000000001" />
    <parent link="gen3_bracelet_link" />
    <child link="gen3_end_effector_link" />
    <axis xyz="0 0 0" />
  </joint>
  <link name="gen3_robotiq_85_base_link">
    <visual>
      <geometry>
        <mesh filename="package://burger_description/vendor/robotiq_description/meshes/visual/robotiq_base.dae" />
      </geometry>
    </visual>
    <collision>
      <geometry>
        <mesh filename="package://burger_description/vendor/robotiq_description/meshes/collision/robotiq_base.stl" />
      </geometry>
    </collision>
    <inertial>
      <origin rpy="0 0 0" xyz="0.0 2.274e-05 0.03232288" />
      <mass value="6.6320197e-01" />
      <inertia ixx="5.1617816e-04" ixy="2.936e-8" ixz="0.0" iyy="5.8802208e-04" iyz="-3.2296e-7" izz="3.9462776e-04" />
    </inertial>
  </link>
  <link name="gen3_robotiq_85_left_knuckle_link">
    <visual>
      <geometry>
        <mesh filename="package://burger_description/vendor/robotiq_description/meshes/visual/left_knuckle.dae" />
      </geometry>
    </visual>
    <collision>
      <geometry>
        <mesh filename="package://burger_description/vendor/robotiq_description/meshes/collision/left_knuckle.stl" />
      </geometry>
    </collision>
    <inertial>
      <origin rpy="0 0 0" xyz="0.01213197 0.0002 -0.00058647" />
      <mass value="1.384773208e-02" />
      <inertia ixx="3.5232e-7" ixy="0.0" ixz="1.1744e-7" iyy="2.31944e-6" iyz="0" izz="2.23136e-6" />
    </inertial>
  </link>
  <link name="gen3_robotiq_85_right_knuckle_link">
    <visual>
      <geometry>
        <mesh filename="package://burger_description/vendor/robotiq_description/meshes/visual/right_knuckle.dae" />
      </geometry>
    </visual>
    <collision>
      <geometry>
        <mesh filename="package://burger_description/vendor/robotiq_description/meshes/collision/right_knuckle.stl" />
      </geometry>
    </collision>
    <inertial>
      <origin rpy="0 0 0" xyz="-0.01213197 0.0002 -0.00058647" />
      <mass value="1.384773208e-02" />
      <inertia ixx="3.5232e-7" ixy="0.0" ixz="-1.1744e-7" iyy="2.31944e-6" iyz="0.0" izz="2.23136e-6" />
    </inertial>
  </link>
  <link name="gen3_robotiq_85_left_finger_link">
    <visual>
      <geometry>
        <mesh filename="package://burger_description/vendor/robotiq_description/meshes/visual/left_finger.dae" />
      </geometry>
    </visual>
    <collision>
      <geometry>
        <mesh filename="package://burger_description/vendor/robotiq_description/meshes/collision/left_finger.stl" />
      </geometry>
    </collision>
    <inertial>
      <origin rpy="0 0 0" xyz="0.00346899 -0.00079447 0.01867121" />
      <mass value="4.260376752e-02" />
      <inertia ixx="1.385792000000000e-05" ixy="0.0" ixz="-2.17264e-06" iyy="1.183208e-05" iyz="0.0" izz="5.19672e-06" />
    </inertial>
  </link>
  <link name="gen3_robotiq_85_right_finger_link">
    <visual>
      <geometry>
        <mesh filename="package://burger_description/vendor/robotiq_description/meshes/visual/right_finger.dae" />
      </geometry>
    </visual>
    <collision>
      <geometry>
        <mesh filename="package://burger_description/vendor/robotiq_description/meshes/collision/right_finger.stl" />
      </geometry>
    </collision>
    <inertial>
      <origin rpy="0 0 0" xyz="-0.00346899 -5.53e-06 0.01867121" />
      <mass value="4.260376752000000e-02" />
      <inertia ixx="1.385792e-05" ixy="0.0" ixz="2.17264e-06" iyy="1.183208e-05" iyz="0.0" izz="5.19672e-06" />
    </inertial>
  </link>
  <link name="gen3_robotiq_85_left_inner_knuckle_link">
    <visual>
      <geometry>
        <mesh filename="package://burger_description/vendor/robotiq_description/meshes/visual/left_inner_knuckle.dae" />
      </geometry>
    </visual>
    <collision>
      <geometry>
        <mesh filename="package://burger_description/vendor/robotiq_description/meshes/collision/left_inner_knuckle.stl" />
      </geometry>
    </collision>
    <inertial>
      <origin rpy="0 0 0" xyz="0.01897699 0.00015001 0.02247101" />
      <mass value="2.969376448e-02" />
      <inertia ixx="9.57136e-06" ixy="0.0" ixz="-3.93424e-06" iyy="8.69056e-06" iyz="0.0" izz="8.19144e-06" />
    </inertial>
  </link>
  <link name="gen3_robotiq_85_right_inner_knuckle_link">
    <visual>
      <geometry>
        <mesh filename="package://burger_description/vendor/robotiq_description/meshes/visual/right_inner_knuckle.dae" />
      </geometry>
    </visual>
    <collision>
      <geometry>
        <mesh filename="package://burger_description/vendor/robotiq_description/meshes/collision/right_inner_knuckle.stl" />
      </geometry>
    </collision>
    <inertial>
      <origin rpy="0 0 0" xyz="-0.01926824 5.001e-05 0.02222178" />
      <mass value="2.969376448e-02" />
      <inertia ixx="9.42456e-06" ixy="0.0" ixz="3.9636e-06" iyy="8.69056e-06" iyz="0.0" izz="8.33824e-06" />
    </inertial>
  </link>
  <link name="gen3_robotiq_85_left_finger_tip_link">
    <visual>
      <geometry>
        <mesh filename="package://burger_description/vendor/robotiq_description/meshes/visual/left_finger_tip.dae" />
      </geometry>
    </visual>
    <collision>
      <geometry>
        <mesh filename="package://burger_description/vendor/robotiq_description/meshes/collision/left_finger_tip.stl" />
      </geometry>
      <surface>
        <friction>
          <ode>
            <mu1>100000.0</mu1>
            <mu2>100000.0</mu2>
          </ode>
        </friction>
        <contact>
          <ode>
            <kp>1e+5</kp>
            <kd>1</kd>
            <soft_cfm>0</soft_cfm>
            <soft_erp>0.2</soft_erp>
            <minDepth>0.002</minDepth>
            <maxVel>0</maxVel>
          </ode>
        </contact>
      </surface>
    </collision>
    <inertial>
      <origin rpy="0 0 0" xyz="-0.01456706 -0.0008 0.01649701" />
      <mass value="4.268588744e-02" />
      <inertia ixx="1.048152e-05" ixy="0.0" ixz="3.5232e-6" iyy="1.197888e-05" iyz="0.0" izz="4.22784e-06" />
    </inertial>
  </link>
  <link name="gen3_robotiq_85_right_finger_tip_link">
    <visual>
      <geometry>
        <mesh filename="package://burger_description/vendor/robotiq_description/meshes/visual/right_finger_tip.dae" />
      </geometry>
    </visual>
    <collision>
      <geometry>
        <mesh filename="package://burger_description/vendor/robotiq_description/meshes/collision/right_finger_tip.stl" />
      </geometry>
      <surface>
        <friction>
          <ode>
            <mu1>100000.0</mu1>
            <mu2>100000.0</mu2>
          </ode>
        </friction>
        <contact>
          <ode>
            <kp>1e+5</kp>
            <kd>1</kd>
            <soft_cfm>0</soft_cfm>
            <soft_erp>0.2</soft_erp>
            <minDepth>0.002</minDepth>
            <maxVel>0</maxVel>
          </ode>
        </contact>
      </surface>
    </collision>
    <inertial>
      <origin rpy="0 0 0" xyz="0.01456706 5e-05 0.01649701" />
      <mass value="4.268588744e-02" />
      <inertia ixx="1.048152e-05" ixy="0.0" ixz="-3.5232e-06" iyy="1.197888e-05" iyz="0.0" izz="4.22784e-06" />
    </inertial>
  </link>
  <joint name="gen3_robotiq_85_base_joint" type="fixed">
    <parent link="gen3_end_effector_link" />
    <child link="gen3_robotiq_85_base_link" />
    <origin rpy="0 0 0" xyz="0 0 0" />
  </joint>
  <joint name="gen3_robotiq_85_left_knuckle_joint" type="revolute">
    <parent link="gen3_robotiq_85_base_link" />
    <child link="gen3_robotiq_85_left_knuckle_link" />
    <axis xyz="0 -1 0" />
    <origin rpy="0 0 0" xyz="0.03060114 0.0 0.05490452" />
    <limit effort="50" lower="0.0" upper="0.8" velocity="0.5" />
  </joint>
  <joint name="gen3_robotiq_85_right_knuckle_joint" type="revolute">
    <parent link="gen3_robotiq_85_base_link" />
    <child link="gen3_robotiq_85_right_knuckle_link" />
    <axis xyz="0 -1 0" />
    <origin rpy="0 0 0" xyz="-0.03060114 0.0 0.05490452" />
    <limit effort="50" lower="-0.8" upper="0.0" velocity="0.5" />
    <mimic joint="gen3_robotiq_85_left_knuckle_joint" multiplier="-1" />
  </joint>
  <joint name="gen3_robotiq_85_left_finger_joint" type="fixed">
    <parent link="gen3_robotiq_85_left_knuckle_link" />
    <child link="gen3_robotiq_85_left_finger_link" />
    <origin rpy="0 0 0" xyz="0.03152616 0.0 -0.00376347" />
  </joint>
  <joint name="gen3_robotiq_85_right_finger_joint" type="fixed">
    <parent link="gen3_robotiq_85_right_knuckle_link" />
    <child link="gen3_robotiq_85_right_finger_link" />
    <origin rpy="0 0 0" xyz="-0.03152616 0.0 -0.00376347" />
  </joint>
  <joint name="gen3_robotiq_85_left_inner_knuckle_joint" type="continuous">
    <parent link="gen3_robotiq_85_base_link" />
    <child link="gen3_robotiq_85_left_inner_knuckle_link" />
    <axis xyz="0 -1 0" />
    <origin rpy="0 0 0" xyz="0.0127 0.0 0.06142" />
    <mimic joint="gen3_robotiq_85_left_knuckle_joint" />
  </joint>
  <joint name="gen3_robotiq_85_right_inner_knuckle_joint" type="continuous">
    <parent link="gen3_robotiq_85_base_link" />
    <child link="gen3_robotiq_85_right_inner_knuckle_link" />
    <axis xyz="0 -1 0" />
    <origin rpy="0 0 0" xyz="-0.0127 0.0 0.06142" />
    <mimic joint="gen3_robotiq_85_left_knuckle_joint" multiplier="-1" />
  </joint>
  <joint name="gen3_robotiq_85_left_finger_tip_joint" type="continuous">
    <parent link="gen3_robotiq_85_left_finger_link" />
    <child link="gen3_robotiq_85_left_finger_tip_link" />
    <axis xyz="0 -1 0" />
    <origin rpy="0 0 0" xyz="0.00563134 0.0 0.04718515" />
    <mimic joint="gen3_robotiq_85_left_knuckle_joint" multiplier="-1" />
  </joint>
  <joint name="gen3_robotiq_85_right_finger_tip_joint" type="continuous">
    <parent link="gen3_robotiq_85_right_finger_link" />
    <child link="gen3_robotiq_85_right_finger_tip_link" />
    <axis xyz="0 -1 0" />
    <origin rpy="0 0 0" xyz="-0.00563134 0.0 0.04718515" />
    <mimic joint="gen3_robotiq_85_left_knuckle_joint" />
  </joint>
  <link name="wrist_camera_link" />
  <joint name="wrist_camera_joint" type="fixed">
    <parent link="gen3_bracelet_link" />
    <child link="wrist_camera_link" />
    <origin rpy="0 1.7444444444444447 -1.5708" xyz="0 -0.06841 -0.05044" />
  </joint>
  <joint name="wrist_mounted_camera_joint" type="fixed">
    <origin rpy="0 0 0" xyz="0 0 0" />
    <parent link="wrist_camera_link" />
    <child link="wrist_mounted_camera_bottom_screw_frame" />
  </joint>
  <link name="wrist_mounted_camera_bottom_screw_frame" />
  <joint name="wrist_mounted_camera_link_joint" type="fixed">
    <origin rpy="0 0 0" xyz="0 0.02 0.0115" />
    <parent link="wrist_mounted_camera_bottom_screw_frame" />
    <child link="wrist_mounted_camera_link" />
  </joint>
  <link name="wrist_mounted_camera_link">
    <visual>
      <origin rpy="0 0 0" xyz="0.00987 -0.02 0" />
      <geometry>
        <box size="0.020 0.099 0.023" />
      </geometry>
      <material name="aluminum" />
    </visual>
    <collision>
      <origin rpy="0 0 0" xyz="0 -0.02 0" />
      <geometry>
        <box size="0.02005 0.099 0.023" />
      </geometry>
    </collision>
    <inertial>
      <mass value="0.072" />
      <origin xyz="0 0 0" />
      <inertia ixx="0.003881243" ixy="0.0" ixz="0.0" iyy="0.000498940" iyz="0.0" izz="0.003879257" />
    </inertial>
  </link>
  <joint name="wrist_mounted_camera_depth_joint" type="fixed">
    <origin rpy="0 0 0" xyz="0 0 0" />
    <parent link="wrist_mounted_camera_link" />
    <child link="wrist_mounted_camera_depth_frame" />
  </joint>
  <link name="wrist_mounted_camera_depth_frame" />
  <joint name="wrist_mounted_camera_depth_optical_joint" type="fixed">
    <origin rpy="-1.5707963267948966 0 -1.5707963267948966" xyz="0 0 0" />
    <parent link="wrist_mounted_camera_depth_frame" />
    <child link="wrist_mounted_camera_depth_optical_frame" />
  </joint>
  <link name="wrist_mounted_camera_depth_optical_frame" />
  <joint name="wrist_mounted_camera_infra1_joint" type="fixed">
    <origin rpy="0 0 0" xyz="0 0.0 0" />
    <parent link="wrist_mounted_camera_link" />
    <child link="wrist_mounted_camera_infra1_frame" />
  </joint>
  <link name="wrist_mounted_camera_infra1_frame" />
  <joint name="wrist_mounted_camera_infra1_optical_joint" type="fixed">
    <origin rpy="-1.5707963267948966 0 -1.5707963267948966" xyz="0 0 0" />
    <parent link="wrist_mounted_camera_infra1_frame" />
    <child link="wrist_mounted_camera_infra1_optical_frame" />
  </joint>
  <link name="wrist_mounted_camera_infra1_optical_frame" />
  <joint name="wrist_mounted_camera_infra2_joint" type="fixed">
    <origin rpy="0 0 0" xyz="0 -0.055 0" />
    <parent link="wrist_mounted_camera_link" />
    <child link="wrist_mounted_camera_infra2_frame" />
  </joint>
  <link name="wrist_mounted_camera_infra2_frame" />
  <joint name="wrist_mounted_camera_infra2_optical_joint" type="fixed">
    <origin rpy="-1.5707963267948966 0 -1.5707963267948966" xyz="0 0 0" />
    <parent link="wrist_mounted_camera_infra2_frame" />
    <child link="wrist_mounted_camera_infra2_optical_frame" />
  </joint>
  <link name="wrist_mounted_camera_infra2_optical_frame" />
  <joint name="wrist_mounted_camera_color_joint" type="fixed">
    <origin rpy="0 0 0" xyz="0 0.015 0" />
    <parent link="wrist_mounted_camera_link" />
    <child link="wrist_mounted_camera_color_frame" />
  </joint>
  <link name="wrist_mounted_camera_color_frame" />
  <joint name="wrist_mounted_camera_color_optical_joint" type="fixed">
    <origin rpy="-1.5707963267948966 0 -1.5707963267948966" xyz="0 0 0" />
    <parent link="wrist_mounted_camera_color_frame" />
    <child link="wrist_mounted_camera_color_optical_frame" />
  </joint>
  <link name="wrist_mounted_camera_color_optical_frame" />
  <link name="wrist_camera_mount_link">
    <inertial>
      <origin rpy="0 0 0" xyz="0.000281 0.011402 -0.029798" />
      <mass value="0.5" />
      <inertia ixx="0.000587" ixy="3E-06" ixz="3E-06" iyy="0.000369" iyz="-0.000118" izz="0.000609" />
    </inertial>
    <visual>
      <origin rpy="0 0 0" xyz="0 0 -0.03" />
      <geometry>
        <box size="0.04 0.08 0.06" />
      </geometry>
      <material name="aluminum">
        <color rgba="0.5 0.5 0.5 1" />
      </material>
    </visual>
    <collision>
      <origin rpy="0 0 0" xyz="0 0 -0.03" />
      <geometry>
        <box size="0.04 0.08 0.06" />
      </geometry>
    </collision>
  </link>
  <joint name="wrist_camera_mount_joint" type="fixed">
    <origin rpy="0 0 0" xyz="0 0 0.0" />
    <parent link="gen3_bracelet_link" />
    <child link="wrist_camera_mount_link" />
  </joint>
  <link name="car1_base_link">
    <inertial>
      <origin xyz="0.0100845530400964 -7.8763397840069E-06 -0.00660483212224633" rpy="0 0 0" />
      <mass value="0.128593928056721" />
      <inertia ixx="5.21456588108558E-05" ixy="-1.24196205891162E-19" ixz="2.93774096227356E-20" iyy="0.000179567040468821" iyz="1.80987590201512E-14" izz="0.00022799348701614" />
    </inertial>
    <visual>
      <origin xyz="0 0 0" rpy="0 0 0" />
      <geometry>
        <mesh filename="package://burger_description/visual/Carro2/meshes/base_link.STL" />
      </geometry>
      <material name="">
        <color rgba="1 1 1 0.3" />
      </material>
    </visual>
    <collision>
      <origin xyz="0 0 0" rpy="0 0 0" />
      <geometry>
        <mesh filename="package://burger_description/visual/Carro2/meshes/base_link.STL" />
      </geometry>
    </collision>
  
    <!-- Added coordinate axes -->
    <visual name="car1_axis_x">
      <origin xyz="0.1 0 0" rpy="0 0 0"/>
      <geometry><mesh filename="package://burger_description/meshes/cube_1m.stl" scale="0.2 0.01 0.01"/></geometry>
      <material name="axis_red"><color rgba="1 0 0 1"/></material>
    </visual>
    <visual name="car1_axis_y">
      <origin xyz="0 0.1 0" rpy="0 0 0"/>
      <geometry><mesh filename="package://burger_description/meshes/cube_1m.stl" scale="0.01 0.2 0.01"/></geometry>
      <material name="axis_green"><color rgba="0 1 0 1"/></material>
    </visual>
    <visual name="car1_axis_z">
      <origin xyz="0 0 0.1" rpy="0 0 0"/>
      <geometry><mesh filename="package://burger_description/meshes/cube_1m.stl" scale="0.01 0.01 0.2"/></geometry>
      <material name="axis_blue"><color rgba="0 0.2 1 1"/></material>
    </visual>
    <visual name="car1_axis_x_head">
      <origin xyz="0.2 0 0" rpy="0 -1.5708 0"/>
      <geometry><mesh filename="package://burger_description/meshes/arrow_pyramid_1m.stl" scale="0.06 0.06 0.08"/></geometry>
      <material name="axis_red"><color rgba="1 0 0 1"/></material>
    </visual>
    <visual name="car1_axis_y_head">
      <origin xyz="0 0.2 0" rpy="1.5708 0 0"/>
      <geometry><mesh filename="package://burger_description/meshes/arrow_pyramid_1m.stl" scale="0.06 0.06 0.08"/></geometry>
      <material name="axis_green"><color rgba="0 1 0 1"/></material>
    </visual>
    <visual name="car1_axis_z_head">
      <origin xyz="0 0 0.2" rpy="0 0 0"/>
      <geometry><mesh filename="package://burger_description/meshes/arrow_pyramid_1m.stl" scale="0.06 0.06 0.08"/></geometry>
      <material name="axis_blue"><color rgba="0 0.2 1 1"/></material>
    </visual>

  </link>
  <link name="car1_Rueda_izquierda_Link">
    <inertial>
      <origin xyz="8.9146E-10 -3.2512E-08 -0.011873" rpy="0 0 0" />
      <mass value="0.021404" />
      <inertia ixx="8.6283E-06" ixy="-6.4381E-11" ixz="-1.062E-13" iyy="8.6269E-06" iyz="-9.8999E-12" izz="1.4515E-05" />
    </inertial>
    <visual>
      <origin xyz="0 0 0" rpy="0 0 0" />
      <geometry>
        <mesh filename="package://burger_description/visual/Carro2/meshes/Rueda_izquierda_Link.STL" />
      </geometry>
      <material name="">
        <color rgba="0.79216 0.81961 0.93333 1" />
      </material>
    </visual>
    <collision>
      <origin xyz="0 0 0" rpy="0 0 0" />
      <geometry>
        <mesh filename="package://burger_description/visual/Carro2/meshes/Rueda_izquierda_Link.STL" />
      </geometry>
    </collision>
  </link>
  <joint name="car1_Rueda_izquierda_Joint" type="continuous">
    <origin xyz="-0.033259 0.08025 -0.01375" rpy="-1.5708 0.042481 0" />
    <parent link="car1_base_link" />
    <child link="car1_Rueda_izquierda_Link" />
    <axis xyz="0 0 1" />
    <limit effort="100" velocity="100" />
    <dynamics damping="0.1" friction="0.1" />
  </joint>
  <link name="car1_Rueda_derecha_Link">
    <inertial>
      <origin xyz="-8.9146E-10 -3.2512E-08 0.011873" rpy="0 0 0" />
      <mass value="0.021404" />
      <inertia ixx="8.6283E-06" ixy="6.4381E-11" ixz="-1.062E-13" iyy="8.6269E-06" iyz="9.8999E-12" izz="1.4515E-05" />
    </inertial>
    <visual>
      <origin xyz="0 0 0" rpy="0 0 0" />
      <geometry>
        <mesh filename="package://burger_description/visual/Carro2/meshes/Rueda_derecha_Link.STL" />
      </geometry>
      <material name="">
        <color rgba="0.79216 0.81961 0.93333 1" />
      </material>
    </visual>
    <collision>
      <origin xyz="0 0 0" rpy="0 0 0" />
      <geometry>
        <mesh filename="package://burger_description/visual/Carro2/meshes/Rueda_derecha_Link.STL" />
      </geometry>
    </collision>
  </link>
  <joint name="car1_Rueda_derecha_Joint" type="continuous">
    <origin xyz="-0.033259 -0.08025 -0.01375" rpy="1.5708 0.042481 -3.1416" />
    <parent link="car1_base_link" />
    <child link="car1_Rueda_derecha_Link" />
    <axis xyz="0 0 1" />
    <limit effort="100" velocity="100" />
    <dynamics damping="0.1" friction="0.1" />
  </joint>
  <link name="car1_Base_rueda_castor_Link">
    <inertial>
      <origin xyz="0.0076868 -0.00024426 0.013506" rpy="0 0 0" />
      <mass value="0.013786" />
      <inertia ixx="1.2468E-06" ixy="9.7727E-10" ixz="-2.4805E-07" iyy="1.3131E-06" iyz="2.4557E-09" izz="1.6977E-06" />
    </inertial>
    <visual>
      <origin xyz="0 0 0" rpy="0 0 0" />
      <geometry>
        <mesh filename="package://burger_description/visual/Carro2/meshes/Base_rueda_castor_Link.STL" />
      </geometry>
      <material name="">
        <color rgba="0.63922 0.66667 0.67843 1" />
      </material>
    </visual>
    <collision>
      <origin xyz="0 0 0" rpy="0 0 0" />
      <geometry>
        <mesh filename="package://burger_description/visual/Carro2/meshes/Base_rueda_castor_Link.STL" />
      </geometry>
    </collision>
  </link>
  <joint name="car1_Base_rueda_castor_Joint" type="continuous">
    <origin xyz="0.072581 0 -0.0025" rpy="3.1416 0 0" />
    <parent link="car1_base_link" />
    <child link="car1_Base_rueda_castor_Link" />
    <axis xyz="0 0 1" />
    <limit effort="100" velocity="100" />
    <dynamics damping="0.1" friction="0.1" />
  </joint>
  <link name="car1_Rueda_castor_Link">
    <inertial>
      <origin xyz="3.4694E-18 -2.6204E-11 -2.7771E-09" rpy="0 0 0" />
      <mass value="0.0082874" />
      <inertia ixx="6.3927E-07" ixy="-7.3317E-23" ixz="5.0431E-23" iyy="6.393E-07" iyz="3.5083E-09" izz="1.0111E-06" />
    </inertial>
    <visual>
      <origin xyz="0 0 0" rpy="0 0 0" />
      <geometry>
        <mesh filename="package://burger_description/visual/Carro2/meshes/Rueda_castor_Link.STL" />
      </geometry>
      <material name="">
        <color rgba="1 1 1 1" />
      </material>
    </visual>
    <collision>
      <origin xyz="0 0 0" rpy="0 0 0" />
      <geometry>
        <mesh filename="package://burger_description/visual/Carro2/meshes/Rueda_castor_Link.STL" />
      </geometry>
    </collision>
  </link>
  <joint name="car1_Rueda_castor_Joint" type="continuous">
    <origin xyz="0.015014 -0.00014167 0.02296" rpy="1.5708 -1.5708 0" />
    <parent link="car1_Base_rueda_castor_Link" />
    <child link="car1_Rueda_castor_Link" />
    <axis xyz="0 0 1" />
    <limit effort="100" velocity="100" />
    <dynamics damping="0.1" friction="0.1" />
  </joint>
  <link name="car2_base_link">
    <inertial>
      <origin xyz="-0.114018971629912 -0.0178599760362418 -2.10435080844746E-05" rpy="0 0 0" />
      <mass value="0.576318693040092" />
      <inertia ixx="0.000483205186547504" ixy="5.61723198415921E-07" ixz="5.39646410035124E-07" iyy="0.00171521897407484" iyz="3.88637031860283E-12" izz="0.00127699776286583" />
    </inertial>
    <visual>
      <origin xyz="0 0 0" rpy="0 0 0" />
      <geometry>
        <mesh filename="package://burger_description/visual/Carro4/meshes/base_link.STL" />
      </geometry>
      <material name="">
        <color rgba="0.752941176470588 0.752941176470588 0.752941176470588 1" />
      </material>
    </visual>
    <collision>
      <origin xyz="0 0 0" rpy="0 0 0" />
      <geometry>
        <mesh filename="package://burger_description/visual/Carro4/meshes/base_link.STL" />
      </geometry>
    </collision>
  
    <!-- Added coordinate axes -->
    <visual name="car2_axis_x">
      <origin xyz="0.1 0 0" rpy="0 0 0"/>
      <geometry><mesh filename="package://burger_description/meshes/cube_1m.stl" scale="0.2 0.01 0.01"/></geometry>
      <material name="axis_red"><color rgba="1 0 0 1"/></material>
    </visual>
    <visual name="car2_axis_y">
      <origin xyz="0 0.1 0" rpy="0 0 0"/>
      <geometry><mesh filename="package://burger_description/meshes/cube_1m.stl" scale="0.01 0.2 0.01"/></geometry>
      <material name="axis_green"><color rgba="0 1 0 1"/></material>
    </visual>
    <visual name="car2_axis_z">
      <origin xyz="0 0 0.1" rpy="0 0 0"/>
      <geometry><mesh filename="package://burger_description/meshes/cube_1m.stl" scale="0.01 0.01 0.2"/></geometry>
      <material name="axis_blue"><color rgba="0 0.2 1 1"/></material>
    </visual>
    <visual name="car2_axis_x_head">
      <origin xyz="0.2 0 0" rpy="0 -1.5708 0"/>
      <geometry><mesh filename="package://burger_description/meshes/arrow_pyramid_1m.stl" scale="0.06 0.06 0.08"/></geometry>
      <material name="axis_red"><color rgba="1 0 0 1"/></material>
    </visual>
    <visual name="car2_axis_y_head">
      <origin xyz="0 0.2 0" rpy="1.5708 0 0"/>
      <geometry><mesh filename="package://burger_description/meshes/arrow_pyramid_1m.stl" scale="0.06 0.06 0.08"/></geometry>
      <material name="axis_green"><color rgba="0 1 0 1"/></material>
    </visual>
    <visual name="car2_axis_z_head">
      <origin xyz="0 0 0.2" rpy="0 0 0"/>
      <geometry><mesh filename="package://burger_description/meshes/arrow_pyramid_1m.stl" scale="0.06 0.06 0.08"/></geometry>
      <material name="axis_blue"><color rgba="0 0.2 1 1"/></material>
    </visual>

  </link>
  <link name="car2_wheel1">
    <inertial>
      <origin xyz="-6.37407689407787E-08 1.36391990229745E-07 -0.0118729806504684" rpy="0 0 0" />
      <mass value="0.0214032206760261" />
      <inertia ixx="8.62753526270547E-06" ixy="9.21421570574685E-12" ixz="-1.19081036562018E-11" iyy="8.62712353240453E-06" iyz="-3.43256908421319E-11" izz="1.45141197799059E-05" />
    </inertial>
    <visual>
      <origin xyz="0 0 0" rpy="0 0 0" />
      <geometry>
        <mesh filename="package://burger_description/visual/Carro4/meshes/wheel1.STL" />
      </geometry>
      <material name="">
        <color rgba="0.792156862745098 0.819607843137255 0.933333333333333 1" />
      </material>
    </visual>
    <collision>
      <origin xyz="0 0 0" rpy="0 0 0" />
      <geometry>
        <mesh filename="package://burger_description/visual/Carro4/meshes/wheel1.STL" />
      </geometry>
    </collision>
  </link>
  <joint name="car2_wheel1" type="continuous">
    <origin xyz="-0.148 0.07825 -0.05835" rpy="-1.5708 0.042481 0" />
    <parent link="car2_base_link" />
    <child link="car2_wheel1" />
    <axis xyz="0 0 1" />
    <limit effort="5" velocity="20" />
    <dynamics damping="0.1" friction="0.1" />
  </joint>
  <link name="car2_wheel2">
    <inertial>
      <origin xyz="-6.37407684619951E-08 1.36391991110985E-07 -0.0118729806504686" rpy="0 0 0" />
      <mass value="0.0214032206760267" />
      <inertia ixx="8.62753526270552E-06" ixy="9.21421572983435E-12" ixz="-1.19081036486571E-11" iyy="8.62712353240479E-06" iyz="-3.43256908798843E-11" izz="1.45141197799062E-05" />
    </inertial>
    <visual>
      <origin xyz="0 0 0" rpy="0 0 0" />
      <geometry>
        <mesh filename="package://burger_description/visual/Carro4/meshes/wheel2.STL" />
      </geometry>
      <material name="">
        <color rgba="0.792156862745098 0.819607843137255 0.933333333333333 1" />
      </material>
    </visual>
    <collision>
      <origin xyz="0 0 0" rpy="0 0 0" />
      <geometry>
        <mesh filename="package://burger_description/visual/Carro4/meshes/wheel2.STL" />
      </geometry>
    </collision>
  </link>
  <joint name="car2_wheel2" type="continuous">
    <origin xyz="-0.037 0.07825 -0.05835" rpy="1.5708 -0.042481 3.1416" />
    <parent link="car2_base_link" />
    <child link="car2_wheel2" />
    <axis xyz="0 0 1" />
    <limit effort="5" velocity="20" />
    <dynamics damping="0.1" friction="0.1" />
  </joint>
  <link name="car2_wheel3">
    <inertial>
      <origin xyz="-6.37407711195914E-08 1.36391990472606E-07 -0.0118729806504681" rpy="0 0 0" />
      <mass value="0.0214032206760236" />
      <inertia ixx="8.62753526270526E-06" ixy="9.21421590569957E-12" ixz="-1.19081039027264E-11" iyy="8.62712353240281E-06" iyz="-3.43256907895468E-11" izz="1.4514119779904E-05" />
    </inertial>
    <visual>
      <origin xyz="0 0 0" rpy="0 0 0" />
      <geometry>
        <mesh filename="package://burger_description/visual/Carro4/meshes/wheel3.STL" />
      </geometry>
      <material name="">
        <color rgba="0.792156862745098 0.819607843137255 0.933333333333333 1" />
      </material>
    </visual>
    <collision>
      <origin xyz="0 0 0" rpy="0 0 0" />
      <geometry>
        <mesh filename="package://burger_description/visual/Carro4/meshes/wheel3.STL" />
      </geometry>
    </collision>
  </link>
  <joint name="car2_wheel3" type="continuous">
    <origin xyz="-0.037 -0.07825 -0.05835" rpy="-1.5708 0.042481 -3.1416" />
    <parent link="car2_base_link" />
    <child link="car2_wheel3" />
    <axis xyz="0 0 1" />
    <limit effort="5" velocity="20" />
    <dynamics damping="0.1" friction="0.1" />
  </joint>
  <link name="car2_wheel4">
    <inertial>
      <origin xyz="-6.37407691905789E-08 1.3639199076404E-07 -0.0118729806504682" rpy="0 0 0" />
      <mass value="0.0214032206760238" />
      <inertia ixx="8.62753526270497E-06" ixy="9.21421579156188E-12" ixz="-1.19081037584655E-11" iyy="8.62712353240329E-06" iyz="-3.43256907885084E-11" izz="1.45141197799043E-05" />
    </inertial>
    <visual>
      <origin xyz="0 0 0" rpy="0 0 0" />
      <geometry>
        <mesh filename="package://burger_description/visual/Carro4/meshes/wheel4.STL" />
      </geometry>
      <material name="">
        <color rgba="0.792156862745098 0.819607843137255 0.933333333333333 1" />
      </material>
    </visual>
    <collision>
      <origin xyz="0 0 0" rpy="0 0 0" />
      <geometry>
        <mesh filename="package://burger_description/visual/Carro4/meshes/wheel4.STL" />
      </geometry>
    </collision>
  </link>
  <joint name="car2_wheel4" type="continuous">
    <origin xyz="-0.148 -0.07825 -0.05835" rpy="1.5708 -0.042481 0" />
    <parent link="car2_base_link" />
    <child link="car2_wheel4" />
    <axis xyz="0 0 1" />
    <limit effort="5" velocity="20" />
    <dynamics damping="0.1" friction="0.1" />
  </joint>
  <joint name="table_to_car1_base" type="fixed">
    <parent link="table_link" />
    <child link="car1_base_link" />
    <origin xyz="-0.300 0.000 0.075" rpy="0.000 0.000 0.000" />
  </joint>
  <joint name="table_to_car2_base" type="fixed">
    <parent link="table_link" />
    <child link="car2_base_link" />
    <origin xyz="0.300 0.000 0.12" rpy="0.000 0.000 0.000" />
  </joint>
</robot>